<?xml version="1.0"?>
<robot xmlns:xacro="http://www.ros.org/wiki/xacro">

  <macro name="model_object" params="name parent color">
  
    <link name="${name}">
      <visual>
        <geometry>
         <mesh filename="file://$(find display)/mesh/cyl_w_closed_handle_in_meters.stl"/>
        </geometry>
        <material name="${color}" />
      </visual>
    </link>
 
   <joint name="${parent}_${name}_base_joint" type="continuous">
      <parent link="${parent}"/>
      <child link="${name}"/>
    </joint> 
   
  </macro>


</robot>

